Workbook

Sheet Backtest Summary
B4: XAU/USD GOLD · HOD / LOD PREDICTIVE SIGNAL · BACKTEST ANALYSIS · FAKE DATA (SYNTHETIC)
B5: Backtest Period: 11 Oct 2006 → 02 Oct 2026 | Total Trading Days: 5,174 | Band: 0.1% | Tolerance: ±0.05%
B8: DUAL HIT RATE | C8: HOD ACCURACY | D8: LOD ACCURACY | E8: OVERALL HIT RATE | F8: MISS RATE | G8: BACKTEST YEARS
B9: ='Statistical Analysis'!E7 -> 0.94008504 | C9: ='Statistical Analysis'!C7 -> 0.96965597 | D9: ='Statistical Analysis'!D7 -> 0.96849633 | E9: ='Statistical Analysis'!F7 -> 0.99806726 | F9: ='Statistical Analysis'!G7 -> 0.0019327406 | G9: 20
B10: =TEXT('Statistical Analysis'!E6,"#,##0")&" / "&TEXT('Statistical Analysis'!E5,"#,##0")&" days" -> 4,864 / 5,174 days | C10: =TEXT('Statistical Analysis'!C6,"#,##0")&" days predicted" -> 5,017 days predicted | D10: =TEXT('Statistical Analysis'!D6,"#,##0")&" days predicted" -> 5,011 days predicted | E10: =TEXT('Statistical Analysis'!F6,"#,##0")&" days (HOD or LOD)" -> 5,164 days (HOD or LOD) | F10: =TEXT('Statistical Analysis'!G6,"#,##0")&" miss days" -> 10 miss days | G10: 2006 – 2026
B13: ▸ ANNUAL PERFORMANCE BREAKDOWN
B14: Year | C14: Days | D14: HOD Hits | E14: LOD Hits | F14: Dual Hits | G14: Either Hits | H14: HOD Rate | I14: LOD Rate | J14: Dual Rate | K14: Overall Rate
B15: 2006 | C15: =COUNTIF('Daily Signal Log'!$S$6:$S$5179,$B15) -> 58 | D15: =COUNTIFS('Daily Signal Log'!$S$6:$S$5179,$B15,'Daily Signal Log'!$K$6:$K$5179,"HIT") -> 56 | E15: =COUNTIFS('Daily Signal Log'!$S$6:$S$5179,$B15,'Daily Signal Log'!$L$6:$L$5179,"HIT") -> 56 | F15: =COUNTIFS('Daily Signal Log'!$S$6:$S$5179,$B15,'Daily Signal Log'!$K$6:$K$5179,"HIT",'Daily Signal Log'!$L$6:$L$5179,"HIT") -> 54 | G15: =D15+E15-F15 -> 58 | H15: =D15/$C15 -> 0.96551724 | I15: =E15/$C15 -> 0.96551724 | J15: =F15/$C15 -> 0.93103448 | K15: =G15/$C15 -> 1
B16: 2007 | C16: =COUNTIF('Daily Signal Log'!$S$6:$S$5179,$B16) -> 260 | D16: =COUNTIFS('Daily Signal Log'!$S$6:$S$5179,$B16,'Daily Signal Log'!$K$6:$K$5179,"HIT") -> 258 | E16: =COUNTIFS('Daily Signal Log'!$S$6:$S$5179,$B16,'Daily Signal Log'!$L$6:$L$5179,"HIT") -> 250 | F16: =COUNTIFS('Daily Signal Log'!$S$6:$S$5179,$B16,'Daily Signal Log'!$K$6:$K$5179,"HIT",'Daily Signal Log'!$L$6:$L$5179,"HIT") -> 248 | G16: =D16+E16-F16 -> 260 | H16: =D16/$C16 -> 0.99230769 | I16: =E16/$C16 -> 0.96153846 | J16: =F16/$C16 -> 0.95384615 | K16: =G16/$C16 -> 1
B17: 2008 | C17: =COUNTIF('Daily Signal Log'!$S$6:$S$5179,$B17) -> 261 | D17: =COUNTIFS('Daily Signal Log'!$S$6:$S$5179,$B17,'Daily Signal Log'!$K$6:$K$5179,"HIT") -> 250 | E17: =COUNTIFS('Daily Signal Log'!$S$6:$S$5179,$B17,'Daily Signal Log'!$L$6:$L$5179,"HIT") -> 249 | F17: =COUNTIFS('Daily Signal Log'!$S$6:$S$5179,$B17,'Daily Signal Log'!$K$6:$K$5179,"HIT",'Daily Signal Log'!$L$6:$L$5179,"HIT") -> 240 | G17: =D17+E17-F17 -> 259 | H17: =D17/$C17 -> 0.95785441 | I17: =E17/$C17 -> 0.95402299 | J17: =F17/$C17 -> 0.91954023 | K17: =G17/$C17 -> 0.99233716
B18: 2009 | C18: =COUNTIF('Daily Signal Log'!$S$6:$S$5179,$B18) -> 261 | D18: =COUNTIFS('Daily Signal Log'!$S$6:$S$5179,$B18,'Daily Signal Log'!$K$6:$K$5179,"HIT") -> 255 | E18: =COUNTIFS('Daily Signal Log'!$S$6:$S$5179,$B18,'Daily Signal Log'!$L$6:$L$5179,"HIT") -> 255 | F18: =COUNTIFS('Daily Signal Log'!$S$6:$S$5179,$B18,'Daily Signal Log'!$K$6:$K$5179,"HIT",'Daily Signal Log'!$L$6:$L$5179,"HIT") -> 251 | G18: =D18+E18-F18 -> 259 | H18: =D18/$C18 -> 0.97701149 | I18: =E18/$C18 -> 0.97701149 | J18: =F18/$C18 -> 0.96168582 | K18: =G18/$C18 -> 0.99233716
B19: 2010 | C19: =COUNTIF('Daily Signal Log'!$S$6:$S$5179,$B19) -> 261 | D19: =COUNTIFS('Daily Signal Log'!$S$6:$S$5179,$B19,'Daily Signal Log'!$K$6:$K$5179,"HIT") -> 254 | E19: =COUNTIFS('Daily Signal Log'!$S$6:$S$5179,$B19,'Daily Signal Log'!$L$6:$L$5179,"HIT") -> 255 | F19: =COUNTIFS('Daily Signal Log'!$S$6:$S$5179,$B19,'Daily Signal Log'!$K$6:$K$5179,"HIT",'Daily Signal Log'!$L$6:$L$5179,"HIT") -> 248 | G19: =D19+E19-F19 -> 261 | H19: =D19/$C19 -> 0.97318008 | I19: =E19/$C19 -> 0.97701149 | J19: =F19/$C19 -> 0.95019157 | K19: =G19/$C19 -> 1
B20: 2011 | C20: =COUNTIF('Daily Signal Log'!$S$6:$S$5179,$B20) -> 260 | D20: =COUNTIFS('Daily Signal Log'!$S$6:$S$5179,$B20,'Daily Signal Log'!$K$6:$K$5179,"HIT") -> 249 | E20: =COUNTIFS('Daily Signal Log'!$S$6:$S$5179,$B20,'Daily Signal Log'!$L$6:$L$5179,"HIT") -> 253 | F20: =COUNTIFS('Daily Signal Log'!$S$6:$S$5179,$B20,'Daily Signal Log'!$K$6:$K$5179,"HIT",'Daily Signal Log'!$L$6:$L$5179,"HIT") -> 244 | G20: =D20+E20-F20 -> 258 | H20: =D20/$C20 -> 0.95769231 | I20: =E20/$C20 -> 0.97307692 | J20: =F20/$C20 -> 0.93846154 | K20: =G20/$C20 -> 0.99230769
B21: 2012 | C21: =COUNTIF('Daily Signal Log'!$S$6:$S$5179,$B21) -> 259 | D21: =COUNTIFS('Daily Signal Log'!$S$6:$S$5179,$B21,'Daily Signal Log'!$K$6:$K$5179,"HIT") -> 253 | E21: =COUNTIFS('Daily Signal Log'!$S$6:$S$5179,$B21,'Daily Signal Log'!$L$6:$L$5179,"HIT") -> 256 | F21: =COUNTIFS('Daily Signal Log'!$S$6:$S$5179,$B21,'Daily Signal Log'!$K$6:$K$5179,"HIT",'Daily Signal Log'!$L$6:$L$5179,"HIT") -> 250 | G21: =D21+E21-F21 -> 259 | H21: =D21/$C21 -> 0.97683398 | I21: =E21/$C21 -> 0.98841699 | J21: =F21/$C21 -> 0.96525097 | K21: =G21/$C21 -> 1
B22: 2013 | C22: =COUNTIF('Daily Signal Log'!$S$6:$S$5179,$B22) -> 259 | D22: =COUNTIFS('Daily Signal Log'!$S$6:$S$5179,$B22,'Daily Signal Log'!$K$6:$K$5179,"HIT") -> 252 | E22: =COUNTIFS('Daily Signal Log'!$S$6:$S$5179,$B22,'Daily Signal Log'!$L$6:$L$5179,"HIT") -> 247 | F22: =COUNTIFS('Daily Signal Log'!$S$6:$S$5179,$B22,'Daily Signal Log'!$K$6:$K$5179,"HIT",'Daily Signal Log'!$L$6:$L$5179,"HIT") -> 240 | G22: =D22+E22-F22 -> 259 | H22: =D22/$C22 -> 0.97297297 | I22: =E22/$C22 -> 0.95366795 | J22: =F22/$C22 -> 0.92664093 | K22: =G22/$C22 -> 1
B23: 2014 | C23: =COUNTIF('Daily Signal Log'!$S$6:$S$5179,$B23) -> 259 | D23: =COUNTIFS('Daily Signal Log'!$S$6:$S$5179,$B23,'Daily Signal Log'!$K$6:$K$5179,"HIT") -> 247 | E23: =COUNTIFS('Daily Signal Log'!$S$6:$S$5179,$B23,'Daily Signal Log'!$L$6:$L$5179,"HIT") -> 253 | F23: =COUNTIFS('Daily Signal Log'!$S$6:$S$5179,$B23,'Daily Signal Log'!$K$6:$K$5179,"HIT",'Daily Signal Log'!$L$6:$L$5179,"HIT") -> 241 | G23: =D23+E23-F23 -> 259 | H23: =D23/$C23 -> 0.95366795 | I23: =E23/$C23 -> 0.97683398 | J23: =F23/$C23 -> 0.93050193 | K23: =G23/$C23 -> 1
B24: 2015 | C24: =COUNTIF('Daily Signal Log'!$S$6:$S$5179,$B24) -> 259 | D24: =COUNTIFS('Daily Signal Log'!$S$6:$S$5179,$B24,'Daily Signal Log'!$K$6:$K$5179,"HIT") -> 251 | E24: =COUNTIFS('Daily Signal Log'!$S$6:$S$5179,$B24,'Daily Signal Log'!$L$6:$L$5179,"HIT") -> 247 | F24: =COUNTIFS('Daily Signal Log'!$S$6:$S$5179,$B24,'Daily Signal Log'!$K$6:$K$5179,"HIT",'Daily Signal Log'!$L$6:$L$5179,"HIT") -> 240 | G24: =D24+E24-F24 -> 258 | H24: =D24/$C24 -> 0.96911197 | I24: =E24/$C24 -> 0.95366795 | J24: =F24/$C24 -> 0.92664093 | K24: =G24/$C24 -> 0.996139
B25: 2016 | C25: =COUNTIF('Daily Signal Log'!$S$6:$S$5179,$B25) -> 259 | D25: =COUNTIFS('Daily Signal Log'!$S$6:$S$5179,$B25,'Daily Signal Log'!$K$6:$K$5179,"HIT") -> 246 | E25: =COUNTIFS('Daily Signal Log'!$S$6:$S$5179,$B25,'Daily Signal Log'!$L$6:$L$5179,"HIT") -> 247 | F25: =COUNTIFS('Daily Signal Log'!$S$6:$S$5179,$B25,'Daily Signal Log'!$K$6:$K$5179,"HIT",'Daily Signal Log'!$L$6:$L$5179,"HIT") -> 234 | G25: =D25+E25-F25 -> 259 | H25: =D25/$C25 -> 0.94980695 | I25: =E25/$C25 -> 0.95366795 | J25: =F25/$C25 -> 0.9034749 | K25: =G25/$C25 -> 1
B26: 2017 | C26: =COUNTIF('Daily Signal Log'!$S$6:$S$5179,$B26) -> 257 | D26: =COUNTIFS('Daily Signal Log'!$S$6:$S$5179,$B26,'Daily Signal Log'!$K$6:$K$5179,"HIT") -> 249 | E26: =COUNTIFS('Daily Signal Log'!$S$6:$S$5179,$B26,'Daily Signal Log'!$L$6:$L$5179,"HIT") -> 246 | F26: =COUNTIFS('Daily Signal Log'!$S$6:$S$5179,$B26,'Daily Signal Log'!$K$6:$K$5179,"HIT",'Daily Signal Log'!$L$6:$L$5179,"HIT") -> 238 | G26: =D26+E26-F26 -> 257 | H26: =D26/$C26 -> 0.9688716 | I26: =E26/$C26 -> 0.95719844 | J26: =F26/$C26 -> 0.92607004 | K26: =G26/$C26 -> 1
... B35: 2026 | C35: =COUNTIF('Daily Signal Log'!$S$6:$S$5179,$B35) -> 195 | D35: =COUNTIFS('Daily Signal Log'!$S$6:$S$5179,$B35,'Daily Signal Log'!$K$6:$K$5179,"HIT") -> 193 | E35: =COUNTIFS('Daily Signal Log'!$S$6:$S$5179,$B35,'Daily Signal Log'!$L$6:$L$5179,"HIT") -> 193 | F35: =COUNTIFS('Daily Signal Log'!$S$6:$S$5179,$B35,'Daily Signal Log'!$K$6:$K$5179,"HIT",'Daily Signal Log'!$L$6:$L$5179,"HIT") -> 191 | G35: =D35+E35-F35 -> 195 | H35: =D35/$C35 -> 0.98974359 | I35: =E35/$C35 -> 0.98974359 | J35: =F35/$C35 -> 0.97948718 | K35: =G35/$C35 -> 1
B36: Total | C36: =SUM(C15:C35) -> 5174 | D36: =SUM(D15:D35) -> 5017 | E36: =SUM(E15:E35) -> 5011 | F36: =SUM(F15:F35) -> 4864 | G36: =SUM(G15:G35) -> 5164 | H36: =D36/$C36 -> 0.96965597 | I36: =E36/$C36 -> 0.96849633 | J36: =F36/$C36 -> 0.94008504 | K36: =G36/$C36 -> 0.99806726
B39: ▸ STRATEGY METHODOLOGY & PARAMETERS
B40: Security | C40: OANDA:XAUUSD (Gold Spot / U.S. Dollar)
B41: Signal Type | C41: Daily HOD / LOD Predictive Model — Daily Level Forecasting
B42: Prediction Window | C42: Pre-session signal generated before the 17:00 ET daily open
B43: Predicted Band | C43: Each prediction is a 0.1% thick price band (Pred High = Pred Low × 1.001)
B44: Hit Condition | C44: Actual High/Low inside the predicted band, or within ±0.05% of its nearest edge
B45: Error % Definition | C45: 0 inside the band; otherwise |Actual − nearest band edge| ÷ Actual
B46: Tolerance Band | C46: ±0.05% (fixed)
B47: Data Source | C47: TradingView · OANDA:XAUUSD · OHLC Daily (real prices)
B48: Predicted Levels | C48: SYNTHETIC — generated for demonstration; not output of a real model
B49: Slippage Model | C49: Not applied — signal is level-based, not execution-based
B50: Run Date | C50: 02 Oct 2026
B52: Past performance is not indicative of future results. Past backtests can be very overfitted giving unrealistic results. You are liable for your own losses.
B54: FAKE DATA — SYNTHETIC BACKTEST. Predicted HOD/LOD levels are generated, not produced by a real model. OHLC prices are real OANDA XAU/USD data.

Sheet Daily Signal Log
B1: XAU/USD Gold Spot — HOD/LOD Daily Signal Log · FAKE DATA (SYNTHETIC)
B2: Security: OANDA:XAUUSD | Period: 11-Oct-2006 to 02-Oct-2026 | Band: 0.1% | Tolerance: ±0.05% | Total Days: 5,174 | Dual Hit Rate: 94.0%
B3: Band Thickness | C3: 0.001 | E3: Tolerance (±) | F3: 0.0005 | H3: Error% = 0 inside band, else distance to nearest band edge ÷ actual price. HIT when Error% ≤ Tolerance.
B5: Date | C5: Open | D5: High | E5: Low | F5: Close | G5: Pred HOD High | H5: Pred HOD Low | I5: Pred LOD High | J5: Pred LOD Low | K5: HOD Hit | L5: LOD Hit | M5: Result | N5: HOD Err% | O5: LOD Err% | P5: Log Return | Q5: RVol 20D (ann.) | R5: Band Width% | S5: Year | T5: Weekday
B6: 39001 | C6: 572.9 | D6: 579.35 | E6: 570.35 | F6: 573.3 | G6: 579.99 | H6: 579.41 | I6: 572.16 | J6: 571.59 | K6: =IF(N6<=$F$3,"HIT","MISS") -> HIT | L6: =IF(O6<=$F$3,"HIT","MISS") -> MISS | M6: =IF(AND(K6="HIT",L6="HIT"),"HOD ✓ | LOD ✓",IF(K6="HIT","HOD ✓",IF(L6="HIT","LOD ✓","✗ MISS"))) -> HOD ✓ | N6: =IF(D6<H6,(H6-D6)/D6,IF(D6>G6,(D6-G6)/D6,0)) -> 0.00010356434 | O6: =IF(E6<J6,(J6-E6)/E6,IF(E6>I6,(E6-I6)/E6,0)) -> 0.0021741036 | R6: =(G6-H6)/H6 -> 0.0010010183 | S6: =YEAR(B6) -> 2006 | T6: =WEEKDAY(B6) -> 4
B7: 39002 | C7: 573.3 | D7: 579.2 | E7: 571.25 | F7: 579.1 | G7: 579.31 | H7: 578.73 | I7: 571.46 | J7: 570.89 | K7: =IF(N7<=$F$3,"HIT","MISS") -> HIT | L7: =IF(O7<=$F$3,"HIT","MISS") -> HIT | M7: =IF(AND(K7="HIT",L7="HIT"),"HOD ✓ | LOD ✓",IF(K7="HIT","HOD ✓",IF(L7="HIT","LOD ✓","✗ MISS"))) -> HOD ✓ | LOD ✓ | N7: =IF(D7<H7,(H7-D7)/D7,IF(D7>G7,(D7-G7)/D7,0)) -> 0 | O7: =IF(E7<J7,(J7-E7)/E7,IF(E7>I7,(E7-I7)/E7,0)) -> 0 | P7: =LN(F7/F6) -> 0.010066034 | R7: =(G7-H7)/H7 -> 0.0010021945 | S7: =YEAR(B7) -> 2006 | T7: =WEEKDAY(B7) -> 5
B8: 39003 | C8: 579.1 | D8: 590.55 | E8: 577.15 | F8: 590.45 | G8: 591.18 | H8: 590.59 | I8: 577.58 | J8: 577 | K8: =IF(N8<=$F$3,"HIT","MISS") -> HIT | L8: =IF(O8<=$F$3,"HIT","MISS") -> HIT | M8: =IF(AND(K8="HIT",L8="HIT"),"HOD ✓ | LOD ✓",IF(K8="HIT","HOD ✓",IF(L8="HIT","LOD ✓","✗ MISS"))) -> HOD ✓ | LOD ✓ | N8: =IF(D8<H8,(H8-D8)/D8,IF(D8>G8,(D8-G8)/D8,0)) -> 6.7733469e-05 | O8: =IF(E8<J8,(J8-E8)/E8,IF(E8>I8,(E8-I8)/E8,0)) -> 0 | P8: =LN(F8/F7) -> 0.019409784 | R8: =(G8-H8)/H8 -> 0.000999001 | S8: =YEAR(B8) -> 2006 | T8: =WEEKDAY(B8) -> 6
B9: 39006 | C9: 590.45 | D9: 596.45 | E9: 590.15 | F9: 595.9 | G9: 596.66 | H9: 596.06 | I9: 591.69 | J9: 591.1 | K9: =IF(N9<=$F$3,"HIT","MISS") -> HIT | L9: =IF(O9<=$F$3,"HIT","MISS") -> MISS | M9: =IF(AND(K9="HIT",L9="HIT"),"HOD ✓ | LOD ✓",IF(K9="HIT","HOD ✓",IF(L9="HIT","LOD ✓","✗ MISS"))) -> HOD ✓ | N9: =IF(D9<H9,(H9-D9)/D9,IF(D9>G9,(D9-G9)/D9,0)) -> 0 | O9: =IF(E9<J9,(J9-E9)/E9,IF(E9>I9,(E9-I9)/E9,0)) -> 0.0016097602 | P9: =LN(F9/F8) -> 0.0091879097 | R9: =(G9-H9)/H9 -> 0.0010066101 | S9: =YEAR(B9) -> 2006 | T9: =WEEKDAY(B9) -> 2
B10: 39007 | C10: 595.9 | D10: 597.9 | E10: 586.15 | F10: 590.3 | G10: 598.7 | H10: 598.1 | I10: 586.38 | J10: 585.79 | K10: =IF(N10<=$F$3,"HIT","MISS") -> HIT | L10: =IF(O10<=$F$3,"HIT","MISS") -> HIT | M10: =IF(AND(K10="HIT",L10="HIT"),"HOD ✓ | LOD ✓",IF(K10="HIT","HOD ✓",IF(L10="HIT","LOD ✓","✗ MISS"))) -> HOD ✓ | LOD ✓ | N10: =IF(D10<H10,(H10-D10)/D10,IF(D10>G10,(D10-G10)/D10,0)) -> 0.0003345041 | O10: =IF(E10<J10,(J10-E10)/E10,IF(E10>I10,(E10-I10)/E10,0)) -> 0 | P10: =LN(F10/F9) -> -0.0094419855 | R10: =(G10-H10)/H10 -> 0.0010031767 | S10: =YEAR(B10) -> 2006 | T10: =WEEKDAY(B10) -> 3
B11: 39008 | C11: 590.3 | D11: 595.35 | E11: 587.45 | F11: 590.3 | G11: 595.54 | H11: 594.95 | I11: 587.39 | J11: 586.8 | K11: =IF(N11<=$F$3,"HIT","MISS") -> HIT | L11: =IF(O11<=$F$3,"HIT","MISS") -> HIT | M11: =IF(AND(K11="HIT",L11="HIT"),"HOD ✓ | LOD ✓",IF(K11="HIT","HOD ✓",IF(L11="HIT","LOD ✓","✗ MISS"))) -> HOD ✓ | LOD ✓ | N11: =IF(D11<H11,(H11-D11)/D11,IF(D11>G11,(D11-G11)/D11,0)) -> 0 | O11: =IF(E11<J11,(J11-E11)/E11,IF(E11>I11,(E11-I11)/E11,0)) -> 0.00010213635 | P11: =LN(F11/F10) -> 0 | R11: =(G11-H11)/H11 -> 0.00099167997 | S11: =YEAR(B11) -> 2006 | T11: =WEEKDAY(B11) -> 4
B12: 39009 | C12: 590.3 | D12: 600.95 | E12: 586.35 | F12: 599.5 | G12: 600.67 | H12: 600.07 | I12: 586.88 | J12: 586.29 | K12: =IF(N12<=$F$3,"HIT","MISS") -> HIT | L12: =IF(O12<=$F$3,"HIT","MISS") -> HIT | M12: =IF(AND(K12="HIT",L12="HIT"),"HOD ✓ | LOD ✓",IF(K12="HIT","HOD ✓",IF(L12="HIT","LOD ✓","✗ MISS"))) -> HOD ✓ | LOD ✓ | N12: =IF(D12<H12,(H12-D12)/D12,IF(D12>G12,(D12-G12)/D12,0)) -> 0.00046592895 | O12: =IF(E12<J12,(J12-E12)/E12,IF(E12>I12,(E12-I12)/E12,0)) -> 0 | P12: =LN(F12/F11) -> 0.015465092 | R12: =(G12-H12)/H12 -> 0.00099988335 | S12: =YEAR(B12) -> 2006 | T12: =WEEKDAY(B12) -> 5
B13: 39010 | C13: 599.5 | D13: 602.75 | E13: 591.55 | F13: 591.55 | G13: 603.03 | H13: 602.43 | I13: 591.41 | J13: 590.82 | K13: =IF(N13<=$F$3,"HIT","MISS") -> HIT | L13: =IF(O13<=$F$3,"HIT","MISS") -> HIT | M13: =IF(AND(K13="HIT",L13="HIT"),"HOD ✓ | LOD ✓",IF(K13="HIT","HOD ✓",IF(L13="HIT","LOD ✓","✗ MISS"))) -> HOD ✓ | LOD ✓ | N13: =IF(D13<H13,(H13-D13)/D13,IF(D13>G13,(D13-G13)/D13,0)) -> 0 | O13: =IF(E13<J13,(J13-E13)/E13,IF(E13>I13,(E13-I13)/E13,0)) -> 0.00023666638 | P13: =LN(F13/F12) -> -0.013349764 | R13: =(G13-H13)/H13 -> 0.00099596634 | S13: =YEAR(B13) -> 2006 | T13: =WEEKDAY(B13) -> 6
B14: 39013 | C14: 591.55 | D14: 593.85 | E14: 579.95 | F14: 582.1 | G14: 593.25 | H14: 592.66 | I14: 580.69 | J14: 580.11 | K14: =IF(N14<=$F$3,"HIT","MISS") -> MISS | L14: =IF(O14<=$F$3,"HIT","MISS") -> HIT | M14: =IF(AND(K14="HIT",L14="HIT"),"HOD ✓ | LOD ✓",IF(K14="HIT","HOD ✓",IF(L14="HIT","LOD ✓","✗ MISS"))) -> LOD ✓ | N14: =IF(D14<H14,(H14-D14)/D14,IF(D14>G14,(D14-G14)/D14,0)) -> 0.0010103562 | O14: =IF(E14<J14,(J14-E14)/E14,IF(E14>I14,(E14-I14)/E14,0)) -> 0.00027588585 | P14: =LN(F14/F13) -> -0.016103956 | R14: =(G14-H14)/H14 -> 0.00099551176 | S14: =YEAR(B14) -> 2006 | T14: =WEEKDAY(B14) -> 2
B15: 39014 | C15: 582.1 | D15: 586.75 | E15: 572.95 | F15: 586.3 | G15: 586.5 | H15: 585.91 | I15: 573.65 | J15: 573.08 | K15: =IF(N15<=$F$3,"HIT","MISS") -> HIT | L15: =IF(O15<=$F$3,"HIT","MISS") -> HIT | M15: =IF(AND(K15="HIT",L15="HIT"),"HOD ✓ | LOD ✓",IF(K15="HIT","HOD ✓",IF(L15="HIT","LOD ✓","✗ MISS"))) -> HOD ✓ | LOD ✓ | N15: =IF(D15<H15,(H15-D15)/D15,IF(D15>G15,(D15-G15)/D15,0)) -> 0.00042607584 | O15: =IF(E15<J15,(J15-E15)/E15,IF(E15>I15,(E15-I15)/E15,0)) -> 0.00022689589 | P15: =LN(F15/F14) -> 0.0071893497 | R15: =(G15-H15)/H15 -> 0.0010069806 | S15: =YEAR(B15) -> 2006 | T15: =WEEKDAY(B15) -> 3
B16: 39015 | C16: 586.3 | D16: 592 | E16: 580.05 | F16: 590.9 | G16: 592.77 | H16: 592.18 | I16: 580.75 | J16: 580.17 | K16: =IF(N16<=$F$3,"HIT","MISS") -> HIT | L16: =IF(O16<=$F$3,"HIT","MISS") -> HIT | M16: =IF(AND(K16="HIT",L16="HIT"),"HOD ✓ | LOD ✓",IF(K16="HIT","HOD ✓",IF(L16="HIT","LOD ✓","✗ MISS"))) -> HOD ✓ | LOD ✓ | N16: =IF(D16<H16,(H16-D16)/D16,IF(D16>G16,(D16-G16)/D16,0)) -> 0.00030405405 | O16: =IF(E16<J16,(J16-E16)/E16,IF(E16>I16,(E16-I16)/E16,0)) -> 0.00020687872 | P16: =LN(F16/F15) -> 0.0078151944 | R16: =(G16-H16)/H16 -> 0.00099631869 | S16: =YEAR(B16) -> 2006 | T16: =WEEKDAY(B16) -> 4
B17: 39016 | C17: 590.9 | D17: 598.95 | E17: 590.15 | F17: 597.2 | G17: 598.78 | H17: 598.18 | I17: 590.09 | J17: 589.5 | K17: =IF(N17<=$F$3,"HIT","MISS") -> HIT | L17: =IF(O17<=$F$3,"HIT","MISS") -> HIT | M17: =IF(AND(K17="HIT",L17="HIT"),"HOD ✓ | LOD ✓",IF(K17="HIT","HOD ✓",IF(L17="HIT","LOD ✓","✗ MISS"))) -> HOD ✓ | LOD ✓ | N17: =IF(D17<H17,(H17-D17)/D17,IF(D17>G17,(D17-G17)/D17,0)) -> 0.00028383004 | O17: =IF(E17<J17,(J17-E17)/E17,IF(E17>I17,(E17-I17)/E17,0)) -> 0.00010166907 | P17: =LN(F17/F16) -> 0.010605267 | R17: =(G17-H17)/H17 -> 0.0010030426 | S17: =YEAR(B17) -> 2006 | T17: =WEEKDAY(B17) -> 5
B18: 39017 | C18: 597.2 | D18: 600.35 | E18: 591.95 | F18: 600.05 | G18: 600.8 | H18: 600.2 | I18: 592.38 | J18: 591.79 | K18: =IF(N18<=$F$3,"HIT","MISS") -> HIT | L18: =IF(O18<=$F$3,"HIT","MISS") -> HIT | M18: =IF(AND(K18="HIT",L18="HIT"),"HOD ✓ | LOD ✓",IF(K18="HIT","HOD ✓",IF(L18="HIT","LOD ✓","✗ MISS"))) -> HOD ✓ | LOD ✓ | N18: =IF(D18<H18,(H18-D18)/D18,IF(D18>G18,(D18-G18)/D18,0)) -> 0 | O18: =IF(E18<J18,(J18-E18)/E18,IF(E18>I18,(E18-I18)/E18,0)) -> 0 | P18: =LN(F18/F17) -> 0.0047609194 | R18: =(G18-H18)/H18 -> 0.00099966678 | S18: =YEAR(B18) -> 2006 | T18: =WEEKDAY(B18) -> 6
... B25: 39028 | C25: 623.2 | D25: 629.25 | E25: 622.1 | F25: 625.1 | G25: 629.92 | H25: 629.29 | I25: 622.43 | J25: 621.81 | K25: =IF(N25<=$F$3,"HIT","MISS") -> HIT | L25: =IF(O25<=$F$3,"HIT","MISS") -> HIT | M25: =IF(AND(K25="HIT",L25="HIT"),"HOD ✓ | LOD ✓",IF(K25="HIT","HOD ✓",IF(L25="HIT","LOD ✓","✗ MISS"))) -> HOD ✓ | LOD ✓ | N25: =IF(D25<H25,(H25-D25)/D25,IF(D25>G25,(D25-G25)/D25,0)) -> 6.3567739e-05 | O25: =IF(E25<J25,(J25-E25)/E25,IF(E25>I25,(E25-I25)/E25,0)) -> 0 | P25: =LN(F25/F24) -> 0.0030441424 | R25: =(G25-H25)/H25 -> 0.0010011283 | S25: =YEAR(B25) -> 2006 | T25: =WEEKDAY(B25) -> 3
B26: 39029 | C26: 625.1 | D26: 627.05 | E26: 613.55 | F26: 615.9 | G26: 627.59 | H26: 626.96 | I26: 613.46 | J26: 612.85 | K26: =IF(N26<=$F$3,"HIT","MISS") -> HIT | L26: =IF(O26<=$F$3,"HIT","MISS") -> HIT | M26: =IF(AND(K26="HIT",L26="HIT"),"HOD ✓ | LOD ✓",IF(K26="HIT","HOD ✓",IF(L26="HIT","LOD ✓","✗ MISS"))) -> HOD ✓ | LOD ✓ | N26: =IF(D26<H26,(H26-D26)/D26,IF(D26>G26,(D26-G26)/D26,0)) -> 0 | O26: =IF(E26<J26,(J26-E26)/E26,IF(E26>I26,(E26-I26)/E26,0)) -> 0.00014668731 | P26: =LN(F26/F25) -> -0.014827024 | Q26: =STDEV(P7:P26)*SQRT(252) -> 0.16731547 | R26: =(G26-H26)/H26 -> 0.0010048488 | S26: =YEAR(B26) -> 2006 | T26: =WEEKDAY(B26) -> 4
B27: 39030 | C27: 615.9 | D27: 635.95 | E27: 615.35 | F27: 633.4 | G27: 636.67 | H27: 636.03 | I27: 615.75 | J27: 615.13 | K27: =IF(N27<=$F$3,"HIT","MISS") -> HIT | L27: =IF(O27<=$F$3,"HIT","MISS") -> HIT | M27: =IF(AND(K27="HIT",L27="HIT"),"HOD ✓ | LOD ✓",IF(K27="HIT","HOD ✓",IF(L27="HIT","LOD ✓","✗ MISS"))) -> HOD ✓ | LOD ✓ | N27: =IF(D27<H27,(H27-D27)/D27,IF(D27>G27,(D27-G27)/D27,0)) -> 0.00012579605 | O27: =IF(E27<J27,(J27-E27)/E27,IF(E27>I27,(E27-I27)/E27,0)) -> 0 | P27: =LN(F27/F26) -> 0.028017521 | Q27: =STDEV(P8:P27)*SQRT(252) -> 0.18746109 | R27: =(G27-H27)/H27 -> 0.0010062418 | S27: =YEAR(B27) -> 2006 | T27: =WEEKDAY(B27) -> 5
B28: 39031 | C28: 633.4 | D28: 636.9 | E28: 625.35 | F28: 628.55 | G28: 637.49 | H28: 636.85 | I28: 625.27 | J28: 624.65 | K28: =IF(N28<=$F$3,"HIT","MISS") -> HIT | L28: =IF(O28<=$F$3,"HIT","MISS") -> HIT | M28: =IF(AND(K28="HIT",L28="HIT"),"HOD ✓ | LOD ✓",IF(K28="HIT","HOD ✓",IF(L28="HIT","LOD ✓","✗ MISS"))) -> HOD ✓ | LOD ✓ | N28: =IF(D28<H28,(H28-D28)/D28,IF(D28>G28,(D28-G28)/D28,0)) -> 0 | O28: =IF(E28<J28,(J28-E28)/E28,IF(E28>I28,(E28-I28)/E28,0)) -> 0.00012792836 | P28: =LN(F28/F27) -> -0.0076865547 | Q28: =STDEV(P9:P28)*SQRT(252) -> 0.1834739 | R28: =(G28-H28)/H28 -> 0.0010049462 | S28: =YEAR(B28) -> 2006 | T28: =WEEKDAY(B28) -> 6
B29: 39034 | C29: 628.55 | D29: 632.9 | E29: 613.95 | F29: 625.6 | G29: 633.33 | H29: 632.7 | I29: 614.17 | J29: 613.56 | K29: =IF(N29<=$F$3,"HIT","MISS") -> HIT | L29: =IF(O29<=$F$3,"HIT","MISS") -> HIT | M29: =IF(AND(K29="HIT",L29="HIT"),"HOD ✓ | LOD ✓",IF(K29="HIT","HOD ✓",IF(L29="HIT","LOD ✓","✗ MISS"))) -> HOD ✓ | LOD ✓ | N29: =IF(D29<H29,(H29-D29)/D29,IF(D29>G29,(D29-G29)/D29,0)) -> 0 | O29: =IF(E29<J29,(J29-E29)/E29,IF(E29>I29,(E29-I29)/E29,0)) -> 0 | P29: =LN(F29/F28) -> -0.0047043901 | Q29: =STDEV(P10:P29)*SQRT(252) -> 0.18401286 | R29: =(G29-H29)/H29 -> 0.00099573257 | S29: =YEAR(B29) -> 2006 | T29: =WEEKDAY(B29) -> 2
B30: 39035 | C30: 625.6 | D30: 629.55 | E30: 619 | F30: 621.1 | G30: 629.64 | H30: 629.01 | I30: 619.74 | J30: 619.12 | K30: =IF(N30<=$F$3,"HIT","MISS") -> HIT | L30: =IF(O30<=$F$3,"HIT","MISS") -> HIT | M30: =IF(AND(K30="HIT",L30="HIT"),"HOD ✓ | LOD ✓",IF(K30="HIT","HOD ✓",IF(L30="HIT","LOD ✓","✗ MISS"))) -> HOD ✓ | LOD ✓ | N30: =IF(D30<H30,(H30-D30)/D30,IF(D30>G30,(D30-G30)/D30,0)) -> 0 | O30: =IF(E30<J30,(J30-E30)/E30,IF(E30>I30,(E30-I30)/E30,0)) -> 0.00019386107 | P30: =LN(F30/F29) -> -0.0072190897 | Q30: =STDEV(P11:P30)*SQRT(252) -> 0.18227135 | R30: =(G30-H30)/H30 -> 0.0010015739 | S30: =YEAR(B30) -> 2006 | T30: =WEEKDAY(B30) -> 3
B31: 39036 | C31: 621.1 | D31: 624.95 | E31: 615.65 | F31: 622.75 | G31: 624.87 | H31: 624.25 | I31: 615.72 | J31: 615.1 | K31: =IF(N31<=$F$3,"HIT","MISS") -> HIT | L31: =IF(O31<=$F$3,"HIT","MISS") -> HIT | M31: =IF(AND(K31="HIT",L31="HIT"),"HOD ✓ | LOD ✓",IF(K31="HIT","HOD ✓",IF(L31="HIT","LOD ✓","✗ MISS"))) -> HOD ✓ | LOD ✓ | N31: =IF(D31<H31,(H31-D31)/D31,IF(D31>G31,(D31-G31)/D31,0)) -> 0.00012801024 | O31: =IF(E31<J31,(J31-E31)/E31,IF(E31>I31,(E31-I31)/E31,0)) -> 0 | P31: =LN(F31/F30) -> 0.0026530546 | Q31: =STDEV(P12:P31)*SQRT(252) -> 0.18202352 | R31: =(G31-H31)/H31 -> 0.00099319183 | S31: =YEAR(B31) -> 2006 | T31: =WEEKDAY(B31) -> 4
B32: 39037 | C32: 622.75 | D32: 628.55 | E32: 618.1 | F32: 618.4 | G32: 629.28 | H32: 628.65 | I32: 617.96 | J32: 617.34 | K32: =IF(N32<=$F$3,"HIT","MISS") -> HIT | L32: =IF(O32<=$F$3,"HIT","MISS") -> HIT | M32: =IF(AND(K32="HIT",L32="HIT"),"HOD ✓ | LOD ✓",IF(K32="HIT","HOD ✓",IF(L32="HIT","LOD ✓","✗ MISS"))) -> HOD ✓ | LOD ✓ | N32: =IF(D32<H32,(H32-D32)/D32,IF(D32>G32,(D32-G32)/D32,0)) -> 0.00015909633 | O32: =IF(E32<J32,(J32-E32)/E32,IF(E32>I32,(E32-I32)/E32,0)) -> 0.00022650057 | P32: =LN(F32/F31) -> -0.0070096569 | Q32: =STDEV(P13:P32)*SQRT(252) -> 0.17852824 | R32: =(G32-H32)/H32 -> 0.0010021475 | S32: =YEAR(B32) -> 2006 | T32: =WEEKDAY(B32) -> 5
B33: 39038 | C33: 618.4 | D33: 622.55 | E33: 614.55 | F33: 621.95 | G33: 622.9 | H33: 622.28 | I33: 614.84 | J33: 614.23 | K33: =IF(N33<=$F$3,"HIT","MISS") -> HIT | L33: =IF(O33<=$F$3,"HIT","MISS") -> HIT | M33: =IF(AND(K33="HIT",L33="HIT"),"HOD ✓ | LOD ✓",IF(K33="HIT","HOD ✓",IF(L33="HIT","LOD ✓","✗ MISS"))) -> HOD ✓ | LOD ✓ | N33: =IF(D33<H33,(H33-D33)/D33,IF(D33>G33,(D33-G33)/D33,0)) -> 0 | O33: =IF(E33<J33,(J33-E33)/E33,IF(E33>I33,(E33-I33)/E33,0)) -> 0 | P33: =LN(F33/F32) -> 0.0057242064 | Q33: =STDEV(P14:P33)*SQRT(252) -> 0.17004911 | R33: =(G33-H33)/H33 -> 0.00099633605 | S33: =YEAR(B33) -> 2006 | T33: =WEEKDAY(B33) -> 6
B34: 39041 | C34: 621.95 | D34: 627.25 | E34: 620.45 | F34: 622.7 | G34: 627.2 | H34: 626.57 | I34: 620.82 | J34: 620.2 | K34: =IF(N34<=$F$3,"HIT","MISS") -> HIT | L34: =IF(O34<=$F$3,"HIT","MISS") -> HIT | M34: =IF(AND(K34="HIT",L34="HIT"),"HOD ✓ | LOD ✓",IF(K34="HIT","HOD ✓",IF(L34="HIT","LOD ✓","✗ MISS"))) -> HOD ✓ | LOD ✓ | N34: =IF(D34<H34,(H34-D34)/D34,IF(D34>G34,(D34-G34)/D34,0)) -> 7.9713033e-05 | O34: =IF(E34<J34,(J34-E34)/E34,IF(E34>I34,(E34-I34)/E34,0)) -> 0 | P34: =LN(F34/F33) -> 0.0012051582 | Q34: =STDEV(P15:P34)*SQRT(252) -> 0.1553936 | R34: =(G34-H34)/H34 -> 0.0010054742 | S34: =YEAR(B34) -> 2006 | T34: =WEEKDAY(B34) -> 2
B35: 39042 | C35: 622.7 | D35: 629.15 | E35: 622.4 | F35: 627.4 | G35: 629.19 | H35: 628.56 | I35: 622.71 | J35: 622.09 | K35: =IF(N35<=$F$3,"HIT","MISS") -> HIT | L35: =IF(O35<=$F$3,"HIT","MISS") -> HIT | M35: =IF(AND(K35="HIT",L35="HIT"),"HOD ✓ | LOD ✓",IF(K35="HIT","HOD ✓",IF(L35="HIT","LOD ✓","✗ MISS"))) -> HOD ✓ | LOD ✓ | N35: =IF(D35<H35,(H35-D35)/D35,IF(D35>G35,(D35-G35)/D35,0)) -> 0 | O35: =IF(E35<J35,(J35-E35)/E35,IF(E35>I35,(E35-I35)/E35,0)) -> 0 | P35: =LN(F35/F34) -> 0.0075194339 | Q35: =STDEV(P16:P35)*SQRT(252) -> 0.15550555 | R35: =(G35-H35)/H35 -> 0.001002291 | S35: =YEAR(B35) -> 2006 | T35: =WEEKDAY(B35) -> 3
B36: 39043 | C36: 627.4 | D36: 634.95 | E36: 626.15 | F36: 630.1 | G36: 634.79 | H36: 634.16 | I36: 626.71 | J36: 626.08 | K36: =IF(N36<=$F$3,"HIT","MISS") -> HIT | L36: =IF(O36<=$F$3,"HIT","MISS") -> HIT | M36: =IF(AND(K36="HIT",L36="HIT"),"HOD ✓ | LOD ✓",IF(K36="HIT","HOD ✓",IF(L36="HIT","LOD ✓","✗ MISS"))) -> HOD ✓ | LOD ✓ | N36: =IF(D36<H36,(H36-D36)/D36,IF(D36>G36,(D36-G36)/D36,0)) -> 0.00025198835 | O36: =IF(E36<J36,(J36-E36)/E36,IF(E36>I36,(E36-I36)/E36,0)) -> 0 | P36: =LN(F36/F35) -> 0.0042942412 | Q36: =STDEV(P17:P36)*SQRT(252) -> 0.15467597 | R36: =(G36-H36)/H36 -> 0.00099344014 | S36: =YEAR(B36) -> 2006 | T36: =WEEKDAY(B36) -> 4
B37: 39044 | C37: 630.1 | D37: 632.25 | E37: 628.55 | F37: 631 | G37: 632.79 | H37: 632.16 | I37: 628.62 | J37: 627.99 | K37: =IF(N37<=$F$3,"HIT","MISS") -> HIT | L37: =IF(O37<=$F$3,"HIT","MISS") -> HIT | M37: =IF(AND(K37="HIT",L37="HIT"),"HOD ✓ | LOD ✓",IF(K37="HIT","HOD ✓",IF(L37="HIT","LOD ✓","✗ MISS"))) -> HOD ✓ | LOD ✓ | N37: =IF(D37<H37,(H37-D37)/D37,IF(D37>G37,(D37-G37)/D37,0)) -> 0 | O37: =IF(E37<J37,(J37-E37)/E37,IF(E37>I37,(E37-I37)/E37,0)) -> 0 | P37: =LN(F37/F36) -> 0.0014273256 | Q37: =STDEV(P18:P37)*SQRT(252) -> 0.1522694 | R37: =(G37-H37)/H37 -> 0.00099658314 | S37: =YEAR(B37) -> 2006 | T37: =WEEKDAY(B37) -> 5
... B5179: 46297 | C5179: 4175.965 | D5179: 4196.895 | E5179: 4133.715 | F5179: 4182.855 | G5179: 4202.58 | H5179: 4198.38 | I5179: 4132.33 | J5179: 4128.2 | K5179: =IF(N5179<=$F$3,"HIT","MISS") -> HIT | L5179: =IF(O5179<=$F$3,"HIT","MISS") -> HIT | M5179: =IF(AND(K5179="HIT",L5179="HIT"),"HOD ✓ | LOD ✓",IF(K5179="HIT","HOD ✓",IF(L5179="HIT","LOD ✓","✗ MISS"))) -> HOD ✓ | LOD ✓ | N5179: =IF(D5179<H5179,(H5179-D5179)/D5179,IF(D5179>G5179,(D5179-G5179)/D5179,0)) -> 0.00035383301 | O5179: =IF(E5179<J5179,(J5179-E5179)/E5179,IF(E5179>I5179,(E5179-I5179)/E5179,0)) -> 0.00033504971 | P5179: =LN(F5179/F5178) -> 0.0013085751 | Q5179: =STDEV(P5160:P5179)*SQRT(252) -> 0.21397807 | R5179: =(G5179-H5179)/H5179 -> 0.0010003859 | S5179: =YEAR(B5179) -> 2026 | T5179: =WEEKDAY(B5179) -> 6
B5181: FAKE DATA — SYNTHETIC BACKTEST. Predicted HOD/LOD levels are generated, not produced by a real model. OHLC prices are real OANDA XAU/USD data.

Sheet Statistical Analysis
B1: XAU/USD HOD/LOD Signal — Statistical Analysis · FAKE DATA (SYNTHETIC)
B3: ▸ OVERALL HIT RATE SUMMARY
B4: Metric | C4: HOD | D4: LOD | E4: Dual (Both) | F4: Either (OR) | G4: Miss
B5: Total Trading Days | C5: =COUNTA('Daily Signal Log'!$B$6:$B$5179) -> 5174 | D5: =COUNTA('Daily Signal Log'!$B$6:$B$5179) -> 5174 | E5: =COUNTA('Daily Signal Log'!$B$6:$B$5179) -> 5174 | F5: =COUNTA('Daily Signal Log'!$B$6:$B$5179) -> 5174 | G5: =COUNTA('Daily Signal Log'!$B$6:$B$5179) -> 5174
B6: Signal Hits | C6: =COUNTIF('Daily Signal Log'!$K$6:$K$5179,"HIT") -> 5017 | D6: =COUNTIF('Daily Signal Log'!$L$6:$L$5179,"HIT") -> 5011 | E6: =COUNTIFS('Daily Signal Log'!$K$6:$K$5179,"HIT",'Daily Signal Log'!$L$6:$L$5179,"HIT") -> 4864 | F6: =C6+D6-E6 -> 5164 | G6: =COUNTIFS('Daily Signal Log'!$K$6:$K$5179,"MISS",'Daily Signal Log'!$L$6:$L$5179,"MISS") -> 10
B7: Accuracy Rate | C7: =C6/C5 -> 0.96965597 | D7: =D6/D5 -> 0.96849633 | E7: =E6/E5 -> 0.94008504 | F7: =F6/F5 -> 0.99806726 | G7: =G6/G5 -> 0.0019327406
B8: Avg Prediction Error | C8: =AVERAGE('Daily Signal Log'!$N$6:$N$5179) -> 0.00015688485 | D8: =AVERAGE('Daily Signal Log'!$O$6:$O$5179) -> 0.00015873738 | E8: — | F8: — | G8: —
B9: Median Prediction Error | C9: =MEDIAN('Daily Signal Log'!$N$6:$N$5179) -> 7.6667444e-05 | D9: =MEDIAN('Daily Signal Log'!$O$6:$O$5179) -> 7.99471e-05 | E9: — | F9: — | G9: —
B10: Avg Error on HIT days | C10: =AVERAGEIF('Daily Signal Log'!$K$6:$K$5179,"HIT",'Daily Signal Log'!$N$6:$N$5179) -> 0.00011076468 | D10: =AVERAGEIF('Daily Signal Log'!$L$6:$L$5179,"HIT",'Daily Signal Log'!$O$6:$O$5179) -> 0.00011000357 | E10: — | F10: — | G10: —
B11: Avg Error on MISS days | C11: =AVERAGEIF('Daily Signal Log'!$K$6:$K$5179,"MISS",'Daily Signal Log'!$N$6:$N$5179) -> 0.0016306739 | D11: =AVERAGEIF('Daily Signal Log'!$L$6:$L$5179,"MISS",'Daily Signal Log'!$O$6:$O$5179) -> 0.0016569282 | E11: — | F11: — | G11: —
B12: Days Actual Inside Band (0.000% err) | C12: =COUNTIF('Daily Signal Log'!$N$6:$N$5179,0) -> 2328 | D12: =COUNTIF('Daily Signal Log'!$O$6:$O$5179,0) -> 2288
B14: ▸ STREAK ANALYSIS
B15: Longest Dual-Hit Winning Streak | C15: 116
B16: Longest Either-Hit Streak | C16: 1169
B17: Longest Miss Streak (Both missed) | C17: 1
B19: ▸ MONTHLY DUAL HIT RATE ANALYSIS
B20: Best Month (Dual Hit Rate) | C20: 2026-09 | D20: 1
B21: Worst Month (Dual Hit Rate) | C21: 2018-02 | D21: 0.7
B22: Months ≥ 95% Dual Hit Rate | C22: 142
B23: Months < 85% Dual Hit Rate | C23: 11
B24: Months Analysed (≥10 sessions) | C24: 240
B26: ▸ DAY-OF-WEEK DUAL HIT RATE
B27: Day | C27: Dual Hit Rate | D27: Sample Days
B28: Monday | C28: =COUNTIFS('Daily Signal Log'!$T$6:$T$5179,2,'Daily Signal Log'!$K$6:$K$5179,"HIT",'Daily Signal Log'!$L$6:$L$5179,"HIT")/D28 -> 0.95251938 | D28: =COUNTIF('Daily Signal Log'!$T$6:$T$5179,2) -> 1032
B29: Tuesday | C29: =COUNTIFS('Daily Signal Log'!$T$6:$T$5179,3,'Daily Signal Log'!$K$6:$K$5179,"HIT",'Daily Signal Log'!$L$6:$L$5179,"HIT")/D29 -> 0.94417709 | D29: =COUNTIF('Daily Signal Log'!$T$6:$T$5179,3) -> 1039
B30: Wednesday | C30: =COUNTIFS('Daily Signal Log'!$T$6:$T$5179,4,'Daily Signal Log'!$K$6:$K$5179,"HIT",'Daily Signal Log'!$L$6:$L$5179,"HIT")/D30 -> 0.93731919 | D30: =COUNTIF('Daily Signal Log'!$T$6:$T$5179,4) -> 1037
B31: Thursday | C31: =COUNTIFS('Daily Signal Log'!$T$6:$T$5179,5,'Daily Signal Log'!$K$6:$K$5179,"HIT",'Daily Signal Log'!$L$6:$L$5179,"HIT")/D31 -> 0.93545279 | D31: =COUNTIF('Daily Signal Log'!$T$6:$T$5179,5) -> 1038
B32: Friday | C32: =COUNTIFS('Daily Signal Log'!$T$6:$T$5179,6,'Daily Signal Log'!$K$6:$K$5179,"HIT",'Daily Signal Log'!$L$6:$L$5179,"HIT")/D32 -> 0.93093385 | D32: =COUNTIF('Daily Signal Log'!$T$6:$T$5179,6) -> 1028
B34: ▸ VOLATILITY REGIME — DUAL HIT RATE BY 20D REALIZED VOL QUINTILE
B35: Vol Regime | C35: Dual Hit Rate | D35: Sample Days | E35: RVol From | F35: RVol To
B36: Q1 (Low Vol) | C36: =COUNTIFS('Daily Signal Log'!$Q$6:$Q$5179,">="&E36,'Daily Signal Log'!$Q$6:$Q$5179,"<"&F36,'Daily Signal Log'!$K$6:$K$5179,"HIT",'Daily Signal Log'!$L$6:$L$5179,"HIT")/D36 -> 0.94762367 | D36: =COUNTIFS('Daily Signal Log'!$Q$6:$Q$5179,">="&E36,'Daily Signal Log'!$Q$6:$Q$5179,"<"&F36) -> 1031 | E36: =MIN('Daily Signal Log'!$Q$6:$Q$5179) -> 0.043254555 | F36: =PERCENTILE('Daily Signal Log'!$Q$6:$Q$5179,0.2) -> 0.10483157
B37: Q2 | C37: =COUNTIFS('Daily Signal Log'!$Q$6:$Q$5179,">="&E37,'Daily Signal Log'!$Q$6:$Q$5179,"<"&F37,'Daily Signal Log'!$K$6:$K$5179,"HIT",'Daily Signal Log'!$L$6:$L$5179,"HIT")/D37 -> 0.93307468 | D37: =COUNTIFS('Daily Signal Log'!$Q$6:$Q$5179,">="&E37,'Daily Signal Log'!$Q$6:$Q$5179,"<"&F37) -> 1031 | E37: =PERCENTILE('Daily Signal Log'!$Q$6:$Q$5179,0.2) -> 0.10483157 | F37: =PERCENTILE('Daily Signal Log'!$Q$6:$Q$5179,0.4) -> 0.13031846
B38: Q3 | C38: =COUNTIFS('Daily Signal Log'!$Q$6:$Q$5179,">="&E38,'Daily Signal Log'!$Q$6:$Q$5179,"<"&F38,'Daily Signal Log'!$K$6:$K$5179,"HIT",'Daily Signal Log'!$L$6:$L$5179,"HIT")/D38 -> 0.93980583 | D38: =COUNTIFS('Daily Signal Log'!$Q$6:$Q$5179,">="&E38,'Daily Signal Log'!$Q$6:$Q$5179,"<"&F38) -> 1030 | E38: =PERCENTILE('Daily Signal Log'!$Q$6:$Q$5179,0.4) -> 0.13031846 | F38: =PERCENTILE('Daily Signal Log'!$Q$6:$Q$5179,0.6) -> 0.15473917
B39: Q4 | C39: =COUNTIFS('Daily Signal Log'!$Q$6:$Q$5179,">="&E39,'Daily Signal Log'!$Q$6:$Q$5179,"<"&F39,'Daily Signal Log'!$K$6:$K$5179,"HIT",'Daily Signal Log'!$L$6:$L$5179,"HIT")/D39 -> 0.94374394 | D39: =COUNTIFS('Daily Signal Log'!$Q$6:$Q$5179,">="&E39,'Daily Signal Log'!$Q$6:$Q$5179,"<"&F39) -> 1031 | E39: =PERCENTILE('Daily Signal Log'!$Q$6:$Q$5179,0.6) -> 0.15473917 | F39: =PERCENTILE('Daily Signal Log'!$Q$6:$Q$5179,0.8) -> 0.20602494
B40: Q5 (High Vol) | C40: =COUNTIFS('Daily Signal Log'!$Q$6:$Q$5179,">="&E40,'Daily Signal Log'!$Q$6:$Q$5179,"<="&F40,'Daily Signal Log'!$K$6:$K$5179,"HIT",'Daily Signal Log'!$L$6:$L$5179,"HIT")/D40 -> 0.93792435 | D40: =COUNTIFS('Daily Signal Log'!$Q$6:$Q$5179,">="&E40,'Daily Signal Log'!$Q$6:$Q$5179,"<="&F40) -> 1031 | E40: =PERCENTILE('Daily Signal Log'!$Q$6:$Q$5179,0.8) -> 0.20602494 | F40: =MAX('Daily Signal Log'!$Q$6:$Q$5179) -> 0.57302434
B41: Quintiles exclude the first 20 sessions (insufficient history for 20D realized vol).
B43: ▸ BAND GEOMETRY CHECK
B44: Min Band Width (Pred High vs Pred Low) | C44: =MIN('Daily Signal Log'!$R$6:$R$5179) -> 0.00099167997
B45: Max Band Width | C45: =MAX('Daily Signal Log'!$R$6:$R$5179) -> 0.0010077207
B46: Avg Band Width | C46: =AVERAGE('Daily Signal Log'!$R$6:$R$5179) -> 0.0010000883
...
